{"status": "resolved", "priority": "critical", "title": "Trac bug crawl explodes", "milestone": "0.10.11", "superceder": "", "nosylist": ["paulproteus, pythonian4000"], "assigned": "paulproteus", "waitingon": "", "keywords": [], "id": "165", "files": [], "history": [{"message": "The problem is fantastic.\n\nLong story short, we're suffering from <a href=\"http://bugs.python.org/issue7185\">http://bugs.python.org/issue7185</a>\n\nFixed on master; deploying!\n   \n", "author": "paulproteus"}, {"message": "It should be easy to write a quick fix for this, but I haven't yet.\n   \n", "author": "paulproteus"}, {"message": "2010-10-17 00:18:44,826 update:208 INFO     Started refreshing all Trac bugs.\nTraceback (most recent call last):\n  File \"./bin/production\", line 78, in &lt;module&gt;\n    djangorecipe.manage.main('mysite.deployment_settings')\n  File\n\"/home/deploy/milestone-a/eggs/djangorecipe-0.20-py2.6.egg/djangorecipe/manage.py\",\nline 16, in main\n    management.execute_manager(mod)\n  File\n\"/home/deploy/milestone-a/parts/production/django/core/management/__init__.py\",\nline 362, in execute_manager\n    utility.execute()\n  File\n\"/home/deploy/milestone-a/parts/production/django/core/management/__init__.py\",\nline 303, in execute\n    self.fetch_command(subcommand).run_from_argv(self.argv)\n  File\n\"/home/deploy/milestone-a/parts/production/django/core/management/base.py\", line\n195, in run_from_argv\n    self.execute(*args, **options.__dict__)\n  File\n\"/home/deploy/milestone-a/parts/production/django/core/management/base.py\", line\n222, in execute\n    output = self.handle(*args, **options)\n  File\n\"/home/deploy/milestone-a/mysite/customs/management/commands/customs_daily_tasks.py\",\nline 156, in handle\n    self.find_and_update_enabled_trac_instances()\n  File\n\"/home/deploy/milestone-a/mysite/customs/management/commands/customs_daily_tasks.py\",\nline 84, in find_and_update_enabled_trac_instances\n    instantiated.update()\n  File \"/home/deploy/milestone-a/mysite/customs/bugtrackers/trac.py\", line 213,\nin update\n    for bug_id in self.generate_list_of_bug_ids_to_look_at():\n  File \"/home/deploy/milestone-a/mysite/customs/bugtrackers/trac.py\", line 199,\nin generate_bug_ids_from_queries\n    mysite.customs.bugtrackers.trac.csv_of_bugs(query_url))\n  File \"/home/deploy/milestone-a/mysite/customs/bugtrackers/trac.py\", line 27,\nin csv_url2list_of_bug_ids\n    return [int(line['id']) for line in dictreader]\nKeyError: 'id'\n   \n", "author": "paulproteus"}]}