{"status": "resolved", "priority": "bug", "title": "In the wiki, AuthDjango tries to destroy sessions that do not exist", "milestone": "0.11.02", "superceder": "", "nosylist": ["paulproteus, pythonian4000"], "assigned": "pythonian4000", "waitingon": "", "keywords": [], "id": "301", "files": [], "history": [{"message": "This is fixed now, as far as I can tell!\n   \n", "author": "paulproteus"}, {"message": "It still gives me the same error. To reproduce, all you need to do (I \nthink) is to log in and then out.\n   \n", "author": "paulproteus"}, {"message": "I have updated the extension to only try and destroy a session if (session_id()\n!= \"\") which should fix this. Asheesh, could you attempt to recreate to confirm\nthe fix?\n   \n", "author": "pythonian4000"}, {"message": "&lt;br&gt;\n&lt;b&gt;Warning&lt;/b&gt;:  session_destroy() [&lt;a\nhref=\"function.session-destroy\"&gt;function.session-destroy&lt;/a&gt;]: Trying to destroy\nuninitialized session in\n&lt;b&gt;/home/wiki/web/wiki/extensions/AuthDjango/AuthDjango.body.php&lt;/b&gt; on line\n&lt;b&gt;258&lt;/b&gt;&lt;br&gt;\n   \n", "author": "paulproteus"}]}