{"status": "resolved", "priority": "urgent", "title": "Urgent bug in middleware -- probably breaks much of the site for many users", "milestone": "", "superceder": "", "nosylist": ["paulproteus"], "assigned": "paulproteus", "waitingon": "", "keywords": [], "id": "51", "files": [], "history": [{"message": "fixed and deployed!\n   \n", "author": "paulproteus"}, {"message": "fixed and deployed!\n   \n", "author": "paulproteus"}, {"message": "[Thu Mar 18 14:22:38 2010] [error] [client 140.77.13.109] Traceback (most recent \ncall last):\n[Thu Mar 18 14:22:38 2010] [error] [client 140.77.13.109]   File \n\"/home/deploy/milestone-\na.buildout/parts/production/django/core/handlers/wsgi.py\", line 245, in __call__\n[Thu Mar 18 14:22:38 2010] [error] [client 140.77.13.109]     response = \nmiddleware_method(request, response)\n[Thu Mar 18 14:22:38 2010] [error] [client 140.77.13.109]   File \n\"/home/deploy/milestone-a.buildout/mysite/base/middleware.py\", line 29, in \nprocess_response\n[Thu Mar 18 14:22:38 2010] [error] [client 140.77.13.109]     \nmysite.project.controllers.take_control_of_our_answers(request.user, \nrequest.session)\n[Thu Mar 18 14:22:38 2010] [error] [client 140.77.13.109] AttributeError: \n'module' object has no attribute 'controllers'\n   \n", "author": "paulproteus"}]}