{"status": "resolved", "priority": "urgent", "title": "python manage.py celeryd currently crashes and burns", "milestone": "0.11.11", "superceder": "", "nosylist": ["jslootbeek, paulproteus"], "assigned": "paulproteus", "waitingon": "", "keywords": [], "id": "613", "files": [], "history": [{"message": "I just fixed this by upgrading bundled django-celery and celery to 2.4.2 and\npushing that to origin/master. Hudson is testing it all; marking as \"resolved\"\nunless Hudson disagrees.\n   \n", "author": "paulproteus"}, {"message": "Trace attached\n\n(oh27)[git:develop+] jule oh-mainline [ which python\n/Users/jule/work/virtualenvs/oh27/bin/python\n(oh27)[git:develop+] jule oh-mainline [ python --version\nPython 2.7.1\n(oh27)[git:develop+] jule oh-mainline [ python manage.py celeryd\nTraceback (most recent call last):\n  File \"manage.py\", line 30, in &lt;module&gt;\n    execute_manager(mysite.settings)\n  File \"/Users/jule/code/oh-\nmainline/vendor/packages/Django/django/core/management/__init__.py\", line 438, in \nexecute_manager\n    utility.execute()\n  File \"/Users/jule/code/oh-\nmainline/vendor/packages/Django/django/core/management/__init__.py\", line 379, in execute\n    self.fetch_command(subcommand).run_from_argv(self.argv)\n  File \"/Users/jule/code/oh-\nmainline/vendor/packages/Django/django/core/management/__init__.py\", line 261, in \nfetch_command\n    klass = load_command_class(app_name, subcommand)\n  File \"/Users/jule/code/oh-\nmainline/vendor/packages/Django/django/core/management/__init__.py\", line 67, in \nload_command_class\n    module = import_module('%s.management.commands.%s' % (app_name, name))\n  File \"/Users/jule/code/oh-mainline/vendor/packages/Django/django/utils/importlib.py\", line 35, \nin import_module\n    __import__(name)\n  File \"/Users/jule/code/oh-mainline/vendor/packages/django-\ncelery/djcelery/management/commands/celeryd.py\", line 8, in &lt;module&gt;\n    from celery.bin import celeryd\nImportError: No module named bin\n   \n", "author": "jslootbeek"}, {"message": "Jule, can you try this, and submit the stack trace to this bug?\n\nGiven a stack trace I can try to see what's going wrong. (As discussed on\nSunday, I can't reproduce the problem on my Debian laptop.)\n   \n", "author": "paulproteus"}, {"message": "If you run:\n\n   python manage.py celeryd\n\nthe interpreter breaks in half with a traceback in django-celery.\n\nWe should fix this pretty soon! This is broken as part of the \"vendor/\"-ification.\n   \n", "author": "paulproteus"}]}