{"status": "resolved", "priority": "urgent", "title": "Visting /customs/ and listing Trac bug tracker causes a crash", "milestone": "", "superceder": "", "nosylist": ["paulproteus"], "assigned": "paulproteus", "waitingon": "", "keywords": [], "id": "759", "files": [], "history": [{"message": "Fixed in <a href=\"https://github.com/openhatch/oh-\">https://github.com/openhatch/oh-</a>\nmainline/commit/29e4be35fdecc17e249a1a8fa26a7b5980d7b1b9\n   \n", "author": "paulproteus"}, {"message": "A pull request that needs review, that I believe addresses the problem correctly: \n<a href=\"https://github.com/openhatch/oh-mainline/pull/63\">https://github.com/openhatch/oh-mainline/pull/63</a>\n   \n", "author": "paulproteus"}, {"message": "The problem seems to be that there is a Trac bug tracker in the database with a \n\"/\" in the name, and urls.py has no way to encode that into a URL.\n\n(I'm working on a fix!)\n   \n", "author": "paulproteus"}]}